Workbook

Sheet Sheet2
A1: Country Code | B1: Mark | C1: Class | D1: Appl. Date | E1: Appl. No. | F1: Reg. Date | G1: Reg. No. | H1: 수신 | I1: 참조 | J1: 국가명칭
A2: OA | B2: DORCO | C2: 21 | D2: 45821 | E2: 3202502194 | H2: =VLOOKUP($A2,Sheet1!$A$1:$E$31, 3, FALSE) -> 'Claire Smedley' <csmedley@vonseidels.com>; 'Chandré Arendse' <cbarendse@vonseidels.com>; poliver@vonseidels.com | I2: 특허법인 성암/전숙현 변리사 <shjeon@sungampat.com>; 'trademark@sungampat.com'; 특허법인 성암/예희남 차장 <trademark22@sungampat.com>; 특허법인 성암/오연지 대리 <trademark37@sungampat.com>; 특허법인 성암/진주 대리 <trademark39@sungampat.com>; 특허법인 성암/양은혜 과장 <trademark42@sungampat.com>; trademark43@sungampat.com | J2: =VLOOKUP($A2,Sheet1!$A$1:$E$31, 5, FALSE) -> OAPI (African Intellectual Property Organization)
A3: OA | B3: DORCO | C3: 8 | D3: 40931 | E3: 3201200185 | F3: 40931 | G3: 70154 | H3: =VLOOKUP($A3,Sheet1!$A$1:$E$31, 3, FALSE) -> 'Claire Smedley' <csmedley@vonseidels.com>; 'Chandré Arendse' <cbarendse@vonseidels.com>; poliver@vonseidels.com | I3: 특허법인 성암/전숙현 변리사 <shjeon@sungampat.com>; 'trademark@sungampat.com'; 특허법인 성암/예희남 차장 <trademark22@sungampat.com>; 특허법인 성암/오연지 대리 <trademark37@sungampat.com>; 특허법인 성암/진주 대리 <trademark39@sungampat.com>; 특허법인 성암/양은혜 과장 <trademark42@sungampat.com>; trademark44@sungampat.com | J3: =VLOOKUP($A3,Sheet1!$A$1:$E$31, 5, FALSE) -> OAPI (African Intellectual Property Organization)
A4: OA | B4: TNB200 Package TYPE2 | C4: 8 | D4: 43922 | E4: 3202001066 | F4: 43922 | G4: 114324 | H4: =VLOOKUP($A4,Sheet1!$A$1:$E$31, 3, FALSE) -> 'Claire Smedley' <csmedley@vonseidels.com>; 'Chandré Arendse' <cbarendse@vonseidels.com>; poliver@vonseidels.com | I4: 특허법인 성암/전숙현 변리사 <shjeon@sungampat.com>; 'trademark@sungampat.com'; 특허법인 성암/예희남 차장 <trademark22@sungampat.com>; 특허법인 성암/오연지 대리 <trademark37@sungampat.com>; 특허법인 성암/진주 대리 <trademark39@sungampat.com>; 특허법인 성암/양은혜 과장 <trademark42@sungampat.com>; trademark45@sungampat.com | J4: =VLOOKUP($A4,Sheet1!$A$1:$E$31, 5, FALSE) -> OAPI (African Intellectual Property Organization)
A5: OA | B5: TNB200 Package TYPE1 | C5: 8 | D5: 43922 | E5: 3202001067 | F5: 43922 | G5: 114325 | H5: =VLOOKUP($A5,Sheet1!$A$1:$E$31, 3, FALSE) -> 'Claire Smedley' <csmedley@vonseidels.com>; 'Chandré Arendse' <cbarendse@vonseidels.com>; poliver@vonseidels.com | I5: 특허법인 성암/전숙현 변리사 <shjeon@sungampat.com>; 'trademark@sungampat.com'; 특허법인 성암/예희남 차장 <trademark22@sungampat.com>; 특허법인 성암/오연지 대리 <trademark37@sungampat.com>; 특허법인 성암/진주 대리 <trademark39@sungampat.com>; 특허법인 성암/양은혜 과장 <trademark42@sungampat.com>; trademark46@sungampat.com | J5: =VLOOKUP($A5,Sheet1!$A$1:$E$31, 5, FALSE) -> OAPI (African Intellectual Property Organization)
A6: OA | B6: FOAM SCRAPER | C6: 8 | D6: 43483 | E6: 106106 | F6: 43570 | G6: 106106 | H6: =VLOOKUP($A6,Sheet1!$A$1:$E$31, 3, FALSE) -> 'Claire Smedley' <csmedley@vonseidels.com>; 'Chandré Arendse' <cbarendse@vonseidels.com>; poliver@vonseidels.com | I6: 특허법인 성암/전숙현 변리사 <shjeon@sungampat.com>; 'trademark@sungampat.com'; 특허법인 성암/예희남 차장 <trademark22@sungampat.com>; 특허법인 성암/오연지 대리 <trademark37@sungampat.com>; 특허법인 성암/진주 대리 <trademark39@sungampat.com>; 특허법인 성암/양은혜 과장 <trademark42@sungampat.com>; trademark47@sungampat.com | J6: =VLOOKUP($A6,Sheet1!$A$1:$E$31, 5, FALSE) -> OAPI (African Intellectual Property Organization)
A7: OA | B7: DORCO TITAN | C7: 8 | D7: 42116 | E7: 3201501252 | F7: 42116 | G7: 83373 | H7: =VLOOKUP($A7,Sheet1!$A$1:$E$31, 3, FALSE) -> 'Claire Smedley' <csmedley@vonseidels.com>; 'Chandré Arendse' <cbarendse@vonseidels.com>; poliver@vonseidels.com | I7: 특허법인 성암/전숙현 변리사 <shjeon@sungampat.com>; 'trademark@sungampat.com'; 특허법인 성암/예희남 차장 <trademark22@sungampat.com>; 특허법인 성암/오연지 대리 <trademark37@sungampat.com>; 특허법인 성암/진주 대리 <trademark39@sungampat.com>; 특허법인 성암/양은혜 과장 <trademark42@sungampat.com>; trademark48@sungampat.com | J7: =VLOOKUP($A7,Sheet1!$A$1:$E$31, 5, FALSE) -> OAPI (African Intellectual Property Organization)
A8: GH | B8: DORCO TITAN | C8: 8 | D8: 43248 | E8: 868/2018 | F8: 44061 | G8: 51618 | H8: =VLOOKUP($A8,Sheet1!$A$1:$E$31, 3, FALSE) -> 'Claire Smedley' <csmedley@vonseidels.com>; 'Chandré Arendse' <cbarendse@vonseidels.com>; poliver@vonseidels.com | I8: 특허법인 성암/전숙현 변리사 <shjeon@sungampat.com>; 'trademark@sungampat.com'; 특허법인 성암/예희남 차장 <trademark22@sungampat.com>; 특허법인 성암/오연지 대리 <trademark37@sungampat.com>; 특허법인 성암/진주 대리 <trademark39@sungampat.com>; 특허법인 성암/양은혜 과장 <trademark42@sungampat.com>; trademark49@sungampat.com | J8: =VLOOKUP($A8,Sheet1!$A$1:$E$31, 5, FALSE) -> Ghana
A9: GM | B9: DORCO TITAN | C9: 8 | D9: 43223 | E9: GM/M/2018/00054 | F9: 44238 | G9: GM/M/2018/00054 | H9: =VLOOKUP($A9,Sheet1!$A$1:$E$31, 3, FALSE) -> 'Claire Smedley' <csmedley@vonseidels.com>; 'Chandré Arendse' <cbarendse@vonseidels.com>; poliver@vonseidels.com | I9: 특허법인 성암/전숙현 변리사 <shjeon@sungampat.com>; 'trademark@sungampat.com'; 특허법인 성암/예희남 차장 <trademark22@sungampat.com>; 특허법인 성암/오연지 대리 <trademark37@sungampat.com>; 특허법인 성암/진주 대리 <trademark39@sungampat.com>; 특허법인 성암/양은혜 과장 <trademark42@sungampat.com>; trademark50@sungampat.com | J9: =VLOOKUP($A9,Sheet1!$A$1:$E$31, 5, FALSE) -> Gambia
A10: NA | B10: DORCO TITAN | C10: 08 | D10: 44942 | E10: NA/T/2023/8 | F10: 45114 | G10: NA/T/2023/8 | H10: =VLOOKUP($A10,Sheet1!$A$1:$E$31, 3, FALSE) -> info@ensafrica.com; rforster@ensafrica.com | I10: 특허법인 성암/전숙현 변리사 <shjeon@sungampat.com>; 'trademark@sungampat.com'; 특허법인 성암/예희남 차장 <trademark22@sungampat.com>; 특허법인 성암/오연지 대리 <trademark37@sungampat.com>; 특허법인 성암/진주 대리 <trademark39@sungampat.com>; 특허법인 성암/양은혜 과장 <trademark42@sungampat.com>; trademark51@sungampat.com | J10: =VLOOKUP($A10,Sheet1!$A$1:$E$31, 5, FALSE) -> Namibia
A11: NA | B11: PACE | C11: 08 | D11: 44942 | E11: NA/T/2023/9 | F11: 45246 | G11: NA/T/2023/9 | H11: =VLOOKUP($A11,Sheet1!$A$1:$E$31, 3, FALSE) -> info@ensafrica.com; rforster@ensafrica.com | I11: 특허법인 성암/전숙현 변리사 <shjeon@sungampat.com>; 'trademark@sungampat.com'; 특허법인 성암/예희남 차장 <trademark22@sungampat.com>; 특허법인 성암/오연지 대리 <trademark37@sungampat.com>; 특허법인 성암/진주 대리 <trademark39@sungampat.com>; 특허법인 성암/양은혜 과장 <trademark42@sungampat.com>; trademark52@sungampat.com | J11: =VLOOKUP($A11,Sheet1!$A$1:$E$31, 5, FALSE) -> Namibia
A12: NA | B12: Prime | C12: 08 | D12: 44942 | E12: NA/T/2023/10 | F12: 45246 | G12: NA/T/2023/10 | H12: =VLOOKUP($A12,Sheet1!$A$1:$E$31, 3, FALSE) -> info@ensafrica.com; rforster@ensafrica.com | I12: 특허법인 성암/전숙현 변리사 <shjeon@sungampat.com>; 'trademark@sungampat.com'; 특허법인 성암/예희남 차장 <trademark22@sungampat.com>; 특허법인 성암/오연지 대리 <trademark37@sungampat.com>; 특허법인 성암/진주 대리 <trademark39@sungampat.com>; 특허법인 성암/양은혜 과장 <trademark42@sungampat.com>; trademark53@sungampat.com | J12: =VLOOKUP($A12,Sheet1!$A$1:$E$31, 5, FALSE) -> Namibia
A13: NG | B13: TNB200 Package TYPE1 | C13: 8 | D13: 43924 | E13: F/TM/O/2020/171323 | H13: =VLOOKUP($A13,Sheet1!$A$1:$E$31, 3, FALSE) -> 'Claire Smedley' <csmedley@vonseidels.com>; 'Chandré Arendse' <cbarendse@vonseidels.com>; poliver@vonseidels.com | I13: 특허법인 성암/전숙현 변리사 <shjeon@sungampat.com>; 'trademark@sungampat.com'; 특허법인 성암/예희남 차장 <trademark22@sungampat.com>; 특허법인 성암/오연지 대리 <trademark37@sungampat.com>; 특허법인 성암/진주 대리 <trademark39@sungampat.com>; 특허법인 성암/양은혜 과장 <trademark42@sungampat.com>; trademark54@sungampat.com | J13: =VLOOKUP($A13,Sheet1!$A$1:$E$31, 5, FALSE) -> Nigeria
A14: NG | B14: TNB200 Package TYPE2 | C14: 8 | D14: 43924 | E14: F/TM/O/2020/171325 | H14: =VLOOKUP($A14,Sheet1!$A$1:$E$31, 3, FALSE) -> 'Claire Smedley' <csmedley@vonseidels.com>; 'Chandré Arendse' <cbarendse@vonseidels.com>; poliver@vonseidels.com | I14: 특허법인 성암/전숙현 변리사 <shjeon@sungampat.com>; 'trademark@sungampat.com'; 특허법인 성암/예희남 차장 <trademark22@sungampat.com>; 특허법인 성암/오연지 대리 <trademark37@sungampat.com>; 특허법인 성암/진주 대리 <trademark39@sungampat.com>; 특허법인 성암/양은혜 과장 <trademark42@sungampat.com>; trademark55@sungampat.com | J14: =VLOOKUP($A14,Sheet1!$A$1:$E$31, 5, FALSE) -> Nigeria
A15: NG | B15: DORCO Design(yellow) | C15: 8 | D15: 41138 | E15: FTM2012/1197 | H15: =VLOOKUP($A15,Sheet1!$A$1:$E$31, 3, FALSE) -> 'Claire Smedley' <csmedley@vonseidels.com>; 'Chandré Arendse' <cbarendse@vonseidels.com>; poliver@vonseidels.com | I15: 특허법인 성암/전숙현 변리사 <shjeon@sungampat.com>; 'trademark@sungampat.com'; 특허법인 성암/예희남 차장 <trademark22@sungampat.com>; 특허법인 성암/오연지 대리 <trademark37@sungampat.com>; 특허법인 성암/진주 대리 <trademark39@sungampat.com>; 특허법인 성암/양은혜 과장 <trademark42@sungampat.com>; trademark56@sungampat.com | J15: =VLOOKUP($A15,Sheet1!$A$1:$E$31, 5, FALSE) -> Nigeria
A16: NG | B16: DORCO Design(blue) | C16: 8 | D16: 41138 | E16: FTM2012/1194 | H16: =VLOOKUP($A16,Sheet1!$A$1:$E$31, 3, FALSE) -> 'Claire Smedley' <csmedley@vonseidels.com>; 'Chandré Arendse' <cbarendse@vonseidels.com>; poliver@vonseidels.com | I16: 특허법인 성암/전숙현 변리사 <shjeon@sungampat.com>; 'trademark@sungampat.com'; 특허법인 성암/예희남 차장 <trademark22@sungampat.com>; 특허법인 성암/오연지 대리 <trademark37@sungampat.com>; 특허법인 성암/진주 대리 <trademark39@sungampat.com>; 특허법인 성암/양은혜 과장 <trademark42@sungampat.com>; trademark57@sungampat.com | J16: =VLOOKUP($A16,Sheet1!$A$1:$E$31, 5, FALSE) -> Nigeria
A17: NG | B17: DORCO TITAN | C17: 8 | D17: 42111 | E17: F/TM/O/2015/49128 | F17: 44508 | G17: 33192 | H17: =VLOOKUP($A17,Sheet1!$A$1:$E$31, 3, FALSE) -> 'Claire Smedley' <csmedley@vonseidels.com>; 'Chandré Arendse' <cbarendse@vonseidels.com>; poliver@vonseidels.com | I17: 특허법인 성암/전숙현 변리사 <shjeon@sungampat.com>; 'trademark@sungampat.com'; 특허법인 성암/예희남 차장 <trademark22@sungampat.com>; 특허법인 성암/오연지 대리 <trademark37@sungampat.com>; 특허법인 성암/진주 대리 <trademark39@sungampat.com>; 특허법인 성암/양은혜 과장 <trademark42@sungampat.com>; trademark58@sungampat.com | J17: =VLOOKUP($A17,Sheet1!$A$1:$E$31, 5, FALSE) -> Nigeria
A18: NG | B18: DORCO | C18: 8 | D18: 34666 | E18: TP22467 | F18: 37223 | G18: 54447 | H18: =VLOOKUP($A18,Sheet1!$A$1:$E$31, 3, FALSE) -> 'Claire Smedley' <csmedley@vonseidels.com>; 'Chandré Arendse' <cbarendse@vonseidels.com>; poliver@vonseidels.com | I18: 특허법인 성암/전숙현 변리사 <shjeon@sungampat.com>; 'trademark@sungampat.com'; 특허법인 성암/예희남 차장 <trademark22@sungampat.com>; 특허법인 성암/오연지 대리 <trademark37@sungampat.com>; 특허법인 성암/진주 대리 <trademark39@sungampat.com>; 특허법인 성암/양은혜 과장 <trademark42@sungampat.com>; trademark59@sungampat.com | J18: =VLOOKUP($A18,Sheet1!$A$1:$E$31, 5, FALSE) -> Nigeria
A19: NG | B19: DORCO SOFT TOUCH | C19: 8 | D19: 40702 | E19: FTM2012/08457 | F19: 42614 | G19: 99637 | H19: =VLOOKUP($A19,Sheet1!$A$1:$E$31, 3, FALSE) -> 'Claire Smedley' <csmedley@vonseidels.com>; 'Chandré Arendse' <cbarendse@vonseidels.com>; poliver@vonseidels.com | I19: 특허법인 성암/전숙현 변리사 <shjeon@sungampat.com>; 'trademark@sungampat.com'; 특허법인 성암/예희남 차장 <trademark22@sungampat.com>; 특허법인 성암/오연지 대리 <trademark37@sungampat.com>; 특허법인 성암/진주 대리 <trademark39@sungampat.com>; 특허법인 성암/양은혜 과장 <trademark42@sungampat.com>; trademark60@sungampat.com | J19: =VLOOKUP($A19,Sheet1!$A$1:$E$31, 5, FALSE) -> Nigeria
A20: NG | B20: New CI | C20: 8 | D20: 40654 | E20: FTM201106642 | H20: =VLOOKUP($A20,Sheet1!$A$1:$E$31, 3, FALSE) -> 'Claire Smedley' <csmedley@vonseidels.com>; 'Chandré Arendse' <cbarendse@vonseidels.com>; poliver@vonseidels.com | I20: 특허법인 성암/전숙현 변리사 <shjeon@sungampat.com>; 'trademark@sungampat.com'; 특허법인 성암/예희남 차장 <trademark22@sungampat.com>; 특허법인 성암/오연지 대리 <trademark37@sungampat.com>; 특허법인 성암/진주 대리 <trademark39@sungampat.com>; 특허법인 성암/양은혜 과장 <trademark42@sungampat.com>; trademark61@sungampat.com | J20: =VLOOKUP($A20,Sheet1!$A$1:$E$31, 5, FALSE) -> Nigeria
A21: NG | B21: SHAI | C21: 8 | D21: 41138 | E21: FTM2012/1150 | H21: =VLOOKUP($A21,Sheet1!$A$1:$E$31, 3, FALSE) -> 'Claire Smedley' <csmedley@vonseidels.com>; 'Chandré Arendse' <cbarendse@vonseidels.com>; poliver@vonseidels.com | I21: 특허법인 성암/전숙현 변리사 <shjeon@sungampat.com>; 'trademark@sungampat.com'; 특허법인 성암/예희남 차장 <trademark22@sungampat.com>; 특허법인 성암/오연지 대리 <trademark37@sungampat.com>; 특허법인 성암/진주 대리 <trademark39@sungampat.com>; 특허법인 성암/양은혜 과장 <trademark42@sungampat.com>; trademark62@sungampat.com | J21: =VLOOKUP($A21,Sheet1!$A$1:$E$31, 5, FALSE) -> Nigeria
A22: NG | B22: PACE | C22: 8 | D22: 41138 | E22: FTM2012/1143 | H22: =VLOOKUP($A22,Sheet1!$A$1:$E$31, 3, FALSE) -> 'Claire Smedley' <csmedley@vonseidels.com>; 'Chandré Arendse' <cbarendse@vonseidels.com>; poliver@vonseidels.com | I22: 특허법인 성암/전숙현 변리사 <shjeon@sungampat.com>; 'trademark@sungampat.com'; 특허법인 성암/예희남 차장 <trademark22@sungampat.com>; 특허법인 성암/오연지 대리 <trademark37@sungampat.com>; 특허법인 성암/진주 대리 <trademark39@sungampat.com>; 특허법인 성암/양은혜 과장 <trademark42@sungampat.com>; trademark63@sungampat.com | J22: =VLOOKUP($A22,Sheet1!$A$1:$E$31, 5, FALSE) -> Nigeria
A23: ZA | B23: New CI | C23: 3 | D23: 42242 | E23: 2015/23804 | F23: 42242 | G23: 2015/23804 | H23: =VLOOKUP($A23,Sheet1!$A$1:$E$31, 3, FALSE) -> 'Claire Smedley' <csmedley@vonseidels.com>; 'Chandré Arendse' <cbarendse@vonseidels.com>; poliver@vonseidels.com | I23: 특허법인 성암/전숙현 변리사 <shjeon@sungampat.com>; 'trademark@sungampat.com'; 특허법인 성암/예희남 차장 <trademark22@sungampat.com>; 특허법인 성암/오연지 대리 <trademark37@sungampat.com>; 특허법인 성암/진주 대리 <trademark39@sungampat.com>; 특허법인 성암/양은혜 과장 <trademark42@sungampat.com>; trademark64@sungampat.com | J23: =VLOOKUP($A23,Sheet1!$A$1:$E$31, 5, FALSE) -> South Africa
A24: ZA | B24: New CI | C24: 8 | D24: 40647 | E24: 201109128 | F24: 40647 | G24: 2011/09128 | H24: =VLOOKUP($A24,Sheet1!$A$1:$E$31, 3, FALSE) -> 'Claire Smedley' <csmedley@vonseidels.com>; 'Chandré Arendse' <cbarendse@vonseidels.com>; poliver@vonseidels.com | I24: 특허법인 성암/전숙현 변리사 <shjeon@sungampat.com>; 'trademark@sungampat.com'; 특허법인 성암/예희남 차장 <trademark22@sungampat.com>; 특허법인 성암/오연지 대리 <trademark37@sungampat.com>; 특허법인 성암/진주 대리 <trademark39@sungampat.com>; 특허법인 성암/양은혜 과장 <trademark42@sungampat.com>; trademark65@sungampat.com | J24: =VLOOKUP($A24,Sheet1!$A$1:$E$31, 5, FALSE) -> South Africa
A25: ZA | B25: SHAI | C25: 8 | D25: 42242 | E25: 2015/23808 | F25: 43791 | G25: 2015/23808 | H25: =VLOOKUP($A25,Sheet1!$A$1:$E$31, 3, FALSE) -> 'Claire Smedley' <csmedley@vonseidels.com>; 'Chandré Arendse' <cbarendse@vonseidels.com>; poliver@vonseidels.com | I25: 특허법인 성암/전숙현 변리사 <shjeon@sungampat.com>; 'trademark@sungampat.com'; 특허법인 성암/예희남 차장 <trademark22@sungampat.com>; 특허법인 성암/오연지 대리 <trademark37@sungampat.com>; 특허법인 성암/진주 대리 <trademark39@sungampat.com>; 특허법인 성암/양은혜 과장 <trademark42@sungampat.com>; trademark66@sungampat.com | J25: =VLOOKUP($A25,Sheet1!$A$1:$E$31, 5, FALSE) -> South Africa
A26: ZA | B26: SHAI | C26: 3 | D26: 42242 | E26: 2015/23807 | F26: 43251 | G26: 2015/23807 | H26: =VLOOKUP($A26,Sheet1!$A$1:$E$31, 3, FALSE) -> 'Claire Smedley' <csmedley@vonseidels.com>; 'Chandré Arendse' <cbarendse@vonseidels.com>; poliver@vonseidels.com | I26: 특허법인 성암/전숙현 변리사 <shjeon@sungampat.com>; 'trademark@sungampat.com'; 특허법인 성암/예희남 차장 <trademark22@sungampat.com>; 특허법인 성암/오연지 대리 <trademark37@sungampat.com>; 특허법인 성암/진주 대리 <trademark39@sungampat.com>; 특허법인 성암/양은혜 과장 <trademark42@sungampat.com>; trademark67@sungampat.com | J26: =VLOOKUP($A26,Sheet1!$A$1:$E$31, 5, FALSE) -> South Africa
A27: ZA | B27: DORCO | C27: 8 | D27: 34689 | E27: 1994/14245 | F27: 35713 | G27: 94/14245 | H27: =VLOOKUP($A27,Sheet1!$A$1:$E$31, 3, FALSE) -> 'Claire Smedley' <csmedley@vonseidels.com>; 'Chandré Arendse' <cbarendse@vonseidels.com>; poliver@vonseidels.com | I27: 특허법인 성암/전숙현 변리사 <shjeon@sungampat.com>; 'trademark@sungampat.com'; 특허법인 성암/예희남 차장 <trademark22@sungampat.com>; 특허법인 성암/오연지 대리 <trademark37@sungampat.com>; 특허법인 성암/진주 대리 <trademark39@sungampat.com>; 특허법인 성암/양은혜 과장 <trademark42@sungampat.com>; trademark68@sungampat.com | J27: =VLOOKUP($A27,Sheet1!$A$1:$E$31, 5, FALSE) -> South Africa
A28: ZA | B28: PACE | C28: 3 | D28: 42242 | E28: 2015/23806 | F28: 43126 | G28: 2015/23806 | H28: =VLOOKUP($A28,Sheet1!$A$1:$E$31, 3, FALSE) -> 'Claire Smedley' <csmedley@vonseidels.com>; 'Chandré Arendse' <cbarendse@vonseidels.com>; poliver@vonseidels.com | I28: 특허법인 성암/전숙현 변리사 <shjeon@sungampat.com>; 'trademark@sungampat.com'; 특허법인 성암/예희남 차장 <trademark22@sungampat.com>; 특허법인 성암/오연지 대리 <trademark37@sungampat.com>; 특허법인 성암/진주 대리 <trademark39@sungampat.com>; 특허법인 성암/양은혜 과장 <trademark42@sungampat.com>; trademark69@sungampat.com | J28: =VLOOKUP($A28,Sheet1!$A$1:$E$31, 5, FALSE) -> South Africa
A29: ZA | B29: PACE | C29: 8 | D29: 41212 | E29: 2012/29429 | F29: 41876 | G29: 2012-29429 | H29: =VLOOKUP($A29,Sheet1!$A$1:$E$31, 3, FALSE) -> 'Claire Smedley' <csmedley@vonseidels.com>; 'Chandré Arendse' <cbarendse@vonseidels.com>; poliver@vonseidels.com | I29: 특허법인 성암/전숙현 변리사 <shjeon@sungampat.com>; 'trademark@sungampat.com'; 특허법인 성암/예희남 차장 <trademark22@sungampat.com>; 특허법인 성암/오연지 대리 <trademark37@sungampat.com>; 특허법인 성암/진주 대리 <trademark39@sungampat.com>; 특허법인 성암/양은혜 과장 <trademark42@sungampat.com>; trademark70@sungampat.com | J29: =VLOOKUP($A29,Sheet1!$A$1:$E$31, 5, FALSE) -> South Africa
A30: ZA | B30: DORCO | C30: 3 | D30: 42242 | E30: 2015/23805 | F30: 43791 | G30: 2015/23805 | H30: =VLOOKUP($A30,Sheet1!$A$1:$E$31, 3, FALSE) -> 'Claire Smedley' <csmedley@vonseidels.com>; 'Chandré Arendse' <cbarendse@vonseidels.com>; poliver@vonseidels.com | I30: 특허법인 성암/전숙현 변리사 <shjeon@sungampat.com>; 'trademark@sungampat.com'; 특허법인 성암/예희남 차장 <trademark22@sungampat.com>; 특허법인 성암/오연지 대리 <trademark37@sungampat.com>; 특허법인 성암/진주 대리 <trademark39@sungampat.com>; 특허법인 성암/양은혜 과장 <trademark42@sungampat.com>; trademark71@sungampat.com | J30: =VLOOKUP($A30,Sheet1!$A$1:$E$31, 5, FALSE) -> South Africa
A31: ZA | B31: DORCO | C31: 16 | D31: 42836 | E31: 2017/10148 | F31: 43553 | G31: 2017/10148 | H31: =VLOOKUP($A31,Sheet1!$A$1:$E$31, 3, FALSE) -> 'Claire Smedley' <csmedley@vonseidels.com>; 'Chandré Arendse' <cbarendse@vonseidels.com>; poliver@vonseidels.com | I31: 특허법인 성암/전숙현 변리사 <shjeon@sungampat.com>; 'trademark@sungampat.com'; 특허법인 성암/예희남 차장 <trademark22@sungampat.com>; 특허법인 성암/오연지 대리 <trademark37@sungampat.com>; 특허법인 성암/진주 대리 <trademark39@sungampat.com>; 특허법인 성암/양은혜 과장 <trademark42@sungampat.com>; trademark72@sungampat.com | J31: =VLOOKUP($A31,Sheet1!$A$1:$E$31, 5, FALSE) -> South Africa
A32: ZA | B32: DORCO EDGE | C32: 8 | D32: 43584 | E32: 2019/11994 | F32: 43584 | G32: 2019/11994 | H32: =VLOOKUP($A32,Sheet1!$A$1:$E$31, 3, FALSE) -> 'Claire Smedley' <csmedley@vonseidels.com>; 'Chandré Arendse' <cbarendse@vonseidels.com>; poliver@vonseidels.com | I32: 특허법인 성암/전숙현 변리사 <shjeon@sungampat.com>; 'trademark@sungampat.com'; 특허법인 성암/예희남 차장 <trademark22@sungampat.com>; 특허법인 성암/오연지 대리 <trademark37@sungampat.com>; 특허법인 성암/진주 대리 <trademark39@sungampat.com>; 특허법인 성암/양은혜 과장 <trademark42@sungampat.com>; trademark73@sungampat.com | J32: =VLOOKUP($A32,Sheet1!$A$1:$E$31, 5, FALSE) -> South Africa
A33: ZA | B33: FOAM SCRAPER | C33: 8 | D33: 43467 | E33: 2019/00151 | F33: 44008 | G33: 2019/00151 | H33: =VLOOKUP($A33,Sheet1!$A$1:$E$31, 3, FALSE) -> 'Claire Smedley' <csmedley@vonseidels.com>; 'Chandré Arendse' <cbarendse@vonseidels.com>; poliver@vonseidels.com | I33: 특허법인 성암/전숙현 변리사 <shjeon@sungampat.com>; 'trademark@sungampat.com'; 특허법인 성암/예희남 차장 <trademark22@sungampat.com>; 특허법인 성암/오연지 대리 <trademark37@sungampat.com>; 특허법인 성암/진주 대리 <trademark39@sungampat.com>; 특허법인 성암/양은혜 과장 <trademark42@sungampat.com>; trademark74@sungampat.com | J33: =VLOOKUP($A33,Sheet1!$A$1:$E$31, 5, FALSE) -> South Africa
A34: ZA | B34: DORCO Eve | C34: 8 | D34: 43279 | E34: 2018/18220 | F34: 44160 | G34: 2018/18220 | H34: =VLOOKUP($A34,Sheet1!$A$1:$E$31, 3, FALSE) -> 'Claire Smedley' <csmedley@vonseidels.com>; 'Chandré Arendse' <cbarendse@vonseidels.com>; poliver@vonseidels.com | I34: 특허법인 성암/전숙현 변리사 <shjeon@sungampat.com>; 'trademark@sungampat.com'; 특허법인 성암/예희남 차장 <trademark22@sungampat.com>; 특허법인 성암/오연지 대리 <trademark37@sungampat.com>; 특허법인 성암/진주 대리 <trademark39@sungampat.com>; 특허법인 성암/양은혜 과장 <trademark42@sungampat.com>; trademark75@sungampat.com | J34: =VLOOKUP($A34,Sheet1!$A$1:$E$31, 5, FALSE) -> South Africa
A35: NI | B35: DORCO Prime | C35: 8 | D35: 44092 | E35: 2020-002238 | F35: 44258 | G35: 2021133041 LM | H35: =VLOOKUP($A35,Sheet1!$A$1:$E$31, 3, FALSE) -> info guybendana.com.ni <info@guybendana.com.ni>; ipprosecution guybendana.com.ni <ipprosecution@guybendana.com.ni>; attorney guybendana.com.ni <attorney@guybendana.com.ni> | I35: 특허법인 성암/전숙현 변리사 <shjeon@sungampat.com>; 'trademark@sungampat.com'; 특허법인 성암/예희남 차장 <trademark22@sungampat.com>; 특허법인 성암/오연지 대리 <trademark37@sungampat.com>; 특허법인 성암/진주 대리 <trademark39@sungampat.com>; 특허법인 성암/양은혜 과장 <trademark42@sungampat.com>; trademark76@sungampat.com | J35: =VLOOKUP($A35,Sheet1!$A$1:$E$31, 5, FALSE) -> Nicaragua
A36: NI | B36: DORUSA | C36: 8 | G36: 700063 | H36: =VLOOKUP($A36,Sheet1!$A$1:$E$31, 3, FALSE) -> info guybendana.com.ni <info@guybendana.com.ni>; ipprosecution guybendana.com.ni <ipprosecution@guybendana.com.ni>; attorney guybendana.com.ni <attorney@guybendana.com.ni> | I36: 특허법인 성암/전숙현 변리사 <shjeon@sungampat.com>; 'trademark@sungampat.com'; 특허법인 성암/예희남 차장 <trademark22@sungampat.com>; 특허법인 성암/오연지 대리 <trademark37@sungampat.com>; 특허법인 성암/진주 대리 <trademark39@sungampat.com>; 특허법인 성암/양은혜 과장 <trademark42@sungampat.com>; trademark77@sungampat.com | J36: =VLOOKUP($A36,Sheet1!$A$1:$E$31, 5, FALSE) -> Nicaragua
A37: NI | B37: DORCO | C37: 8 | D37: 40862 | E37: 2011-004093 | F37: 41794 | G37: 2014104593LM | H37: =VLOOKUP($A37,Sheet1!$A$1:$E$31, 3, FALSE) -> info guybendana.com.ni <info@guybendana.com.ni>; ipprosecution guybendana.com.ni <ipprosecution@guybendana.com.ni>; attorney guybendana.com.ni <attorney@guybendana.com.ni> | I37: 특허법인 성암/전숙현 변리사 <shjeon@sungampat.com>; 'trademark@sungampat.com'; 특허법인 성암/예희남 차장 <trademark22@sungampat.com>; 특허법인 성암/오연지 대리 <trademark37@sungampat.com>; 특허법인 성암/진주 대리 <trademark39@sungampat.com>; 특허법인 성암/양은혜 과장 <trademark42@sungampat.com>; trademark78@sungampat.com | J37: =VLOOKUP($A37,Sheet1!$A$1:$E$31, 5, FALSE) -> Nicaragua
A38: NI | B38: PACE | C38: 8 | D38: 42678 | E38: 2016-004310 | F38: 42912 | G38: M2017119549LM | H38: =VLOOKUP($A38,Sheet1!$A$1:$E$31, 3, FALSE) -> info guybendana.com.ni <info@guybendana.com.ni>; ipprosecution guybendana.com.ni <ipprosecution@guybendana.com.ni>; attorney guybendana.com.ni <attorney@guybendana.com.ni> | I38: 특허법인 성암/전숙현 변리사 <shjeon@sungampat.com>; 'trademark@sungampat.com'; 특허법인 성암/예희남 차장 <trademark22@sungampat.com>; 특허법인 성암/오연지 대리 <trademark37@sungampat.com>; 특허법인 성암/진주 대리 <trademark39@sungampat.com>; 특허법인 성암/양은혜 과장 <trademark42@sungampat.com>; trademark79@sungampat.com | J38: =VLOOKUP($A38,Sheet1!$A$1:$E$31, 5, FALSE) -> Nicaragua
A39: DO | B39: DORCO | C39: 8 | D39: 42136 | E39: 2015-14457 | F39: 44564 | G39: 284037 | H39: =VLOOKUP($A39,Sheet1!$A$1:$E$31, 3, FALSE) -> trademarks@castillo.com.do | I39: 특허법인 성암/전숙현 변리사 <shjeon@sungampat.com>; 'trademark@sungampat.com'; 특허법인 성암/예희남 차장 <trademark22@sungampat.com>; 특허법인 성암/오연지 대리 <trademark37@sungampat.com>; 특허법인 성암/진주 대리 <trademark39@sungampat.com>; 특허법인 성암/양은혜 과장 <trademark42@sungampat.com>; trademark80@sungampat.com | J39: =VLOOKUP($A39,Sheet1!$A$1:$E$31, 5, FALSE) -> Dominican Republic
A40: DO | B40: DORUSA | C40: 8 | D40: 42136 | E40: 2015-14454 | F40: 42720 | G40: 2015-14454 | H40: =VLOOKUP($A40,Sheet1!$A$1:$E$31, 3, FALSE) -> trademarks@castillo.com.do | I40: 특허법인 성암/전숙현 변리사 <shjeon@sungampat.com>; 'trademark@sungampat.com'; 특허법인 성암/예희남 차장 <trademark22@sungampat.com>; 특허법인 성암/오연지 대리 <trademark37@sungampat.com>; 특허법인 성암/진주 대리 <trademark39@sungampat.com>; 특허법인 성암/양은혜 과장 <trademark42@sungampat.com>; trademark81@sungampat.com | J40: =VLOOKUP($A40,Sheet1!$A$1:$E$31, 5, FALSE) -> Dominican Republic
...

Sheet Sheet1
A1: 코드 | B1: 현지대리인 | C1: To | D1: CC
A2: AO | B2: VON | C2: {=_xlfn.XLOOKUP(1, ([1]Sheet1!$A$2:$A$497 = [1]Sheet2!A2) * ([1]Sheet1!$B$2:$B$497 = [1]Sheet2!B2), [1]Sheet1!$D$2:$D$497, "")} -> Claire Smedley <csmedley@vonseidels.com>; Chandré Arendse <cbarendse@vonseidels.com>; Pearlen Oliver <poliver@vonseidels.com> | E2: Angola
A3: BW | B3: ENSAfrica | C3: {=_xlfn.XLOOKUP(1, ([1]Sheet1!$A$2:$A$497 = [1]Sheet2!A3) * ([1]Sheet1!$B$2:$B$497 = [1]Sheet2!B3), [1]Sheet1!$D$2:$D$497, "")} -> info@ensafrica.com; rforster@ensafrica.com | E3: Botswana
A4: CD | B4: VON | C4: {=_xlfn.XLOOKUP(1, ([1]Sheet1!$A$2:$A$497 = [1]Sheet2!A4) * ([1]Sheet1!$B$2:$B$497 = [1]Sheet2!B4), [1]Sheet1!$D$2:$D$497, "")} -> 'Claire Smedley' <csmedley@vonseidels.com>; 'Chandré Arendse' <cbarendse@vonseidels.com>; poliver@vonseidels.com | E4: Democratic Republic of the Congo
A5: CO | B5: CASTELLANOS & Co. | C5: {=_xlfn.XLOOKUP(1, ([1]Sheet1!$A$2:$A$497 = [1]Sheet2!A5) * ([1]Sheet1!$B$2:$B$497 = [1]Sheet2!B5), [1]Sheet1!$D$2:$D$497, "")} -> CASTELLANOS & Co. <castellanos@castellanosyco.co> | E5: Colombia
A6: DJ | B6: VON | C6: {=_xlfn.XLOOKUP(1, ([1]Sheet1!$A$2:$A$497 = [1]Sheet2!A6) * ([1]Sheet1!$B$2:$B$497 = [1]Sheet2!B6), [1]Sheet1!$D$2:$D$497, "")} -> 'Claire Smedley' <csmedley@vonseidels.com>; 'Chandré Arendse' <cbarendse@vonseidels.com>; poliver@vonseidels.com | E6: {=_xlfn.XLOOKUP(1, ([1]Sheet1!$A$2:$A$497 = [1]Sheet2!A6) * ([1]Sheet1!$B$2:$B$497 = [1]Sheet2!B6), [1]Sheet1!$C$2:$C$497, "")} -> Djibouti
A7: DO | B7: Castillo y Castillo | C7: {=_xlfn.XLOOKUP(1, ([1]Sheet1!$A$2:$A$497 = [1]Sheet2!A7) * ([1]Sheet1!$B$2:$B$497 = [1]Sheet2!B7), [1]Sheet1!$D$2:$D$497, "")} -> trademarks@castillo.com.do | E7: {=_xlfn.XLOOKUP(1, ([1]Sheet1!$A$2:$A$497 = [1]Sheet2!A7) * ([1]Sheet1!$B$2:$B$497 = [1]Sheet2!B7), [1]Sheet1!$C$2:$C$497, "")} -> Dominican Republic
A8: ET | B8: VON | C8: {=_xlfn.XLOOKUP(1, ([1]Sheet1!$A$2:$A$497 = [1]Sheet2!A8) * ([1]Sheet1!$B$2:$B$497 = [1]Sheet2!B8), [1]Sheet1!$D$2:$D$497, "")} -> 'Claire Smedley' <csmedley@vonseidels.com>; 'Chandré Arendse' <cbarendse@vonseidels.com>; poliver@vonseidels.com | E8: {=_xlfn.XLOOKUP(1, ([1]Sheet1!$A$2:$A$497 = [1]Sheet2!A8) * ([1]Sheet1!$B$2:$B$497 = [1]Sheet2!B8), [1]Sheet1!$C$2:$C$497, "")} -> Ethiopia
A9: GH | B9: VON | C9: {=_xlfn.XLOOKUP(1, ([1]Sheet1!$A$2:$A$497 = [1]Sheet2!A9) * ([1]Sheet1!$B$2:$B$497 = [1]Sheet2!B9), [1]Sheet1!$D$2:$D$497, "")} -> 'Claire Smedley' <csmedley@vonseidels.com>; 'Chandré Arendse' <cbarendse@vonseidels.com>; poliver@vonseidels.com | E9: {=_xlfn.XLOOKUP(1, ([1]Sheet1!$A$2:$A$497 = [1]Sheet2!A9) * ([1]Sheet1!$B$2:$B$497 = [1]Sheet2!B9), [1]Sheet1!$C$2:$C$497, "")} -> Ghana
A10: GM | B10: VON | C10: {=_xlfn.XLOOKUP(1, ([1]Sheet1!$A$2:$A$497 = [1]Sheet2!A10) * ([1]Sheet1!$B$2:$B$497 = [1]Sheet2!B10), [1]Sheet1!$D$2:$D$497, "")} -> 'Claire Smedley' <csmedley@vonseidels.com>; 'Chandré Arendse' <cbarendse@vonseidels.com>; poliver@vonseidels.com | E10: {=_xlfn.XLOOKUP(1, ([1]Sheet1!$A$2:$A$497 = [1]Sheet2!A10) * ([1]Sheet1!$B$2:$B$497 = [1]Sheet2!B10), [1]Sheet1!$C$2:$C$497, "")} -> Gambia
A11: KE | B11: VON | C11: {=_xlfn.XLOOKUP(1, ([1]Sheet1!$A$2:$A$497 = [1]Sheet2!A11) * ([1]Sheet1!$B$2:$B$497 = [1]Sheet2!B11), [1]Sheet1!$D$2:$D$497, "")} -> 'Claire Smedley' <csmedley@vonseidels.com>; 'Chandré Arendse' <cbarendse@vonseidels.com>; poliver@vonseidels.com | E11: {=_xlfn.XLOOKUP(1, ([1]Sheet1!$A$2:$A$497 = [1]Sheet2!A11) * ([1]Sheet1!$B$2:$B$497 = [1]Sheet2!B11), [1]Sheet1!$C$2:$C$497, "")} -> Kenya
A12: LR | B12: VON | C12: {=_xlfn.XLOOKUP(1, ([1]Sheet1!$A$2:$A$497 = [1]Sheet2!A12) * ([1]Sheet1!$B$2:$B$497 = [1]Sheet2!B12), [1]Sheet1!$D$2:$D$497, "")} -> 'Claire Smedley' <csmedley@vonseidels.com>; 'Chandré Arendse' <cbarendse@vonseidels.com>; poliver@vonseidels.com | E12: {=_xlfn.XLOOKUP(1, ([1]Sheet1!$A$2:$A$497 = [1]Sheet2!A12) * ([1]Sheet1!$B$2:$B$497 = [1]Sheet2!B12), [1]Sheet1!$C$2:$C$497, "")} -> Liberia
A13: MG | B13: ENSAfrica | C13: {=_xlfn.XLOOKUP(1, ([1]Sheet1!$A$2:$A$497 = [1]Sheet2!A13) * ([1]Sheet1!$B$2:$B$497 = [1]Sheet2!B13), [1]Sheet1!$D$2:$D$497, "")} -> info@ensafrica.com; rforster@ensafrica.com | E13: {=_xlfn.XLOOKUP(1, ([1]Sheet1!$A$2:$A$497 = [1]Sheet2!A13) * ([1]Sheet1!$B$2:$B$497 = [1]Sheet2!B13), [1]Sheet1!$C$2:$C$497, "")} -> Madagascar
A14: MI | B14: Tilleke (미얀마) | C14: {=_xlfn.XLOOKUP(1, ([1]Sheet1!$A$2:$A$497 = [1]Sheet2!A14) * ([1]Sheet1!$B$2:$B$497 = [1]Sheet2!B14), [1]Sheet1!$D$2:$D$497, "")} -> Khin Myo Myo Aye <khinmyomyoaye@tilleke.com>; mm.docketing@tilleke.com | E14: {=_xlfn.XLOOKUP(1, ([1]Sheet1!$A$2:$A$497 = [1]Sheet2!A14) * ([1]Sheet1!$B$2:$B$497 = [1]Sheet2!B14), [1]Sheet1!$C$2:$C$497, "")} -> Myanmar (Burma)
A15: MU | B15: ENSAfrica | C15: {=_xlfn.XLOOKUP(1, ([1]Sheet1!$A$2:$A$497 = [1]Sheet2!A15) * ([1]Sheet1!$B$2:$B$497 = [1]Sheet2!B15), [1]Sheet1!$D$2:$D$497, "")} -> info@ensafrica.com; rforster@ensafrica.com | E15: {=_xlfn.XLOOKUP(1, ([1]Sheet1!$A$2:$A$497 = [1]Sheet2!A15) * ([1]Sheet1!$B$2:$B$497 = [1]Sheet2!B15), [1]Sheet1!$C$2:$C$497, "")} -> Mauritius
A16: MW | B16: ENSAfrica | C16: {=_xlfn.XLOOKUP(1, ([1]Sheet1!$A$2:$A$497 = [1]Sheet2!A16) * ([1]Sheet1!$B$2:$B$497 = [1]Sheet2!B16), [1]Sheet1!$D$2:$D$497, "")} -> info@ensafrica.com; rforster@ensafrica.com | E16: {=_xlfn.XLOOKUP(1, ([1]Sheet1!$A$2:$A$497 = [1]Sheet2!A16) * ([1]Sheet1!$B$2:$B$497 = [1]Sheet2!B16), [1]Sheet1!$C$2:$C$497, "")} -> Malawi
A17: MZ | B17: ENSAfrica | C17: {=_xlfn.XLOOKUP(1, ([1]Sheet1!$A$2:$A$497 = [1]Sheet2!A17) * ([1]Sheet1!$B$2:$B$497 = [1]Sheet2!B17), [1]Sheet1!$D$2:$D$497, "")} -> info@ensafrica.com; rforster@ensafrica.com | E17: {=_xlfn.XLOOKUP(1, ([1]Sheet1!$A$2:$A$497 = [1]Sheet2!A17) * ([1]Sheet1!$B$2:$B$497 = [1]Sheet2!B17), [1]Sheet1!$C$2:$C$497, "")} -> Mozambique
... A31: ZZ | B31: VON | C31: {=_xlfn.XLOOKUP(1, ([1]Sheet1!$A$2:$A$497 = [1]Sheet2!A31) * ([1]Sheet1!$B$2:$B$497 = [1]Sheet2!B31), [1]Sheet1!$D$2:$D$497, "")} -> 'Claire Smedley' <csmedley@vonseidels.com>; 'Chandré Arendse' <cbarendse@vonseidels.com>; poliver@vonseidels.com | E31: {=_xlfn.XLOOKUP(1, ([1]Sheet1!$A$2:$A$497 = [1]Sheet2!A31) * ([1]Sheet1!$B$2:$B$497 = [1]Sheet2!B31), [1]Sheet1!$C$2:$C$497, "")} -> Tanzania (Zanzibar)
